Workbook

Sheet Start Here
A1: Fresh Lead Supply Planner
A2: How many new leads the dialler needs each day to keep the team selling.
B4: What this answers
B5: One number: how many brand-new leads must land in the dialler each working day. It is derived, not guessed — from how a lead actually performs on its 1st, 2nd, 3rd and 4th attempt in your own data.
B6: The idea in one line
B7: A lead is not a lead, it is a small budget of attempts. Each attempt returns less than the one before, so a lead is used up after a few dials. Divide the team's daily dialling capacity by how many dials a lead absorbs before it is spent, and you get the number of fresh leads a day it takes to avoid re-dialling exhausted list.
B8: Two formulas, and you take the smaller one
B9: Target-driven: fresh leads/day = sales target per day ÷ sales per lead
B10: Capacity-driven: fresh leads/day = (agents × dials per agent-day) ÷ dials per lead
B11: Order the LOWER of the two. If the target-driven number is higher, no amount of lead buying will fix it — the team cannot physically work them, and surplus leads simply age until they are worth half as much. That case is a hiring problem, and the Planner flags it.
B12: How to use it
B13: 1. Open the Planner tab. Everything shaded yellow is yours to change; green cells are the answers.
B14: 2. Set your sales target, how many agents actually dial on a normal day, and your attempt cap.
B15: 3. Read 'ORDER THIS MANY FRESH LEADS PER DAY'.
... B23: The baseline yield curve is measured from 7,572 leads and 26,115 calls in the IE Telesales base between 20 March and 1 September 2026. Sales are counted once per lead, on the attempt where the sale was stamped. The curve is survivorship-corrected: it asks what share of the leads that actually received attempt N converted on attempt N, rather than the misleading cut of conversion by total attempts, which flatters low attempt counts because a lead that sells stops being dialled.

Sheet Planner
A1: Planner
A2: Yellow = your inputs. Green = the answer. Everything else is calculated.
A4: 1 · THE TARGET
A5: Sales target per working day | B5: 20
A6: Working days per week | B6: 5
A7: Sales target per week | B7: =B5*B6
A9: 2 · HOW YOU WORK A LEAD
A10: Attempt cap (stop dialling after this many) | B10: 4 | C10: Set by economics, not habit — see the break-even below.
A11: Retire leads older than (days) | B11: 30 | C11: Yield collapses past this point in your data.
A12: Yield curve source | B12: Baseline | C12: Baseline = measured Mar-Aug 2026. Auto = recalculated from Paste Calls.
A13: Dials a lead absorbs before it is spent | B13: =INDEX('Yield Curve'!$H$28:$H$35,$B$10)
A14: Sales per lead at this cap | B14: =INDEX('Yield Curve'!$I$28:$I$35,$B$10)
A15: Sales per 100 dials at this cap | B15: =IFERROR(100*B14/B13,"")
A17: 3 · DIALLING CAPACITY
A18: Agents dialling on an average day | B18: 2.5 | C18: Bodies actually on the phone, not headcount on the payroll.
A19: Dials per agent per day | B19: 128 | C19: Your measured median. See the Capacity tab before changing this.
A20: Total dials available per day | B20: =B18*B19
A22: 4 · MONEY
A23: Cost per fresh lead | B23: 3
A24: Agent cost per hour, fully loaded | B24: 18
A25: Paid hours per agent-day | B25: 7.5
A26: Cost of one dial | B26: =IFERROR(B24*B25/B19,"") | C26: Agent time only.
A27: Gross margin per sale | B27: 150
A29: THE ANSWER
A30: Leads/day the sales target requires | B30: =IFERROR(B5/B14,"")
A31: Leads/day the team can actually work | B31: =IFERROR(B20/B13,"")
A32: ORDER THIS MANY FRESH LEADS PER DAY | B32: =IFERROR(MIN(B30,B31),"")
A33: …per week | B33: =IFERROR(B32*B6,"")
A34: Sales/day that volume delivers | B34: =IFERROR(B32*B14,"")
A35: Gap to target | B35: =IFERROR(B34-B5,"") | C35: Negative means the target is out of reach at this headcount.
A37: IS THE TARGET EVEN REACHABLE?
A38: Agents needed to work the target volume | B38: =IFERROR(B30*B13/B19,"")
A39: Agents you are short | B39: =IFERROR(MAX(0,B38-B18),"")
A40: Verdict | B40: =IF(B30>B31,"AGENT-SHORT — buy leads only up to capacity and hire, or surplus leads will age out","LEAD SUPPLY IS THE ONLY GAP — buying to target is enough")
A42: HOW BIG THE LIVE LIST SHOULD BE
A43: Days from first dial to last dial | B43: 9 | C43: Your measured median. p75 is 27 days.
A44: Workable leads to hold in the dialler | B44: =IFERROR(B32*B43,"") | C44: Little's law: arrival rate × cycle time.
A45: Days of untouched cover to keep | B45: 3 | C45: Buffer against lumpy supplier delivery.
A46: Minimum untouched leads in hand | B46: =IFERROR(B32*B45,"")
A48: UNIT ECONOMICS
...

Sheet Scenarios
A1: Scenarios
A2: Fresh leads per day, and the headcount it takes to work them.
A4: FRESH LEADS NEEDED PER DAY
A5: Sales/day target | B5: cap at 2 | C5: cap at 3 | D5: cap at 4 | E5: cap at 5 | F5: cap at 6
A6: 5 | B6: =IFERROR($A6/INDEX('Yield Curve'!$I$28:$I$35,2),"") | C6: =IFERROR($A6/INDEX('Yield Curve'!$I$28:$I$35,3),"") | D6: =IFERROR($A6/INDEX('Yield Curve'!$I$28:$I$35,4),"") | E6: =IFERROR($A6/INDEX('Yield Curve'!$I$28:$I$35,5),"") | F6: =IFERROR($A6/INDEX('Yield Curve'!$I$28:$I$35,6),"")
A7: 10 | B7: =IFERROR($A7/INDEX('Yield Curve'!$I$28:$I$35,2),"") | C7: =IFERROR($A7/INDEX('Yield Curve'!$I$28:$I$35,3),"") | D7: =IFERROR($A7/INDEX('Yield Curve'!$I$28:$I$35,4),"") | E7: =IFERROR($A7/INDEX('Yield Curve'!$I$28:$I$35,5),"") | F7: =IFERROR($A7/INDEX('Yield Curve'!$I$28:$I$35,6),"")
A8: 15 | B8: =IFERROR($A8/INDEX('Yield Curve'!$I$28:$I$35,2),"") | C8: =IFERROR($A8/INDEX('Yield Curve'!$I$28:$I$35,3),"") | D8: =IFERROR($A8/INDEX('Yield Curve'!$I$28:$I$35,4),"") | E8: =IFERROR($A8/INDEX('Yield Curve'!$I$28:$I$35,5),"") | F8: =IFERROR($A8/INDEX('Yield Curve'!$I$28:$I$35,6),"")
A9: 20 | B9: =IFERROR($A9/INDEX('Yield Curve'!$I$28:$I$35,2),"") | C9: =IFERROR($A9/INDEX('Yield Curve'!$I$28:$I$35,3),"") | D9: =IFERROR($A9/INDEX('Yield Curve'!$I$28:$I$35,4),"") | E9: =IFERROR($A9/INDEX('Yield Curve'!$I$28:$I$35,5),"") | F9: =IFERROR($A9/INDEX('Yield Curve'!$I$28:$I$35,6),"")
A10: 25 | B10: =IFERROR($A10/INDEX('Yield Curve'!$I$28:$I$35,2),"") | C10: =IFERROR($A10/INDEX('Yield Curve'!$I$28:$I$35,3),"") | D10: =IFERROR($A10/INDEX('Yield Curve'!$I$28:$I$35,4),"") | E10: =IFERROR($A10/INDEX('Yield Curve'!$I$28:$I$35,5),"") | F10: =IFERROR($A10/INDEX('Yield Curve'!$I$28:$I$35,6),"")
A11: 30 | B11: =IFERROR($A11/INDEX('Yield Curve'!$I$28:$I$35,2),"") | C11: =IFERROR($A11/INDEX('Yield Curve'!$I$28:$I$35,3),"") | D11: =IFERROR($A11/INDEX('Yield Curve'!$I$28:$I$35,4),"") | E11: =IFERROR($A11/INDEX('Yield Curve'!$I$28:$I$35,5),"") | F11: =IFERROR($A11/INDEX('Yield Curve'!$I$28:$I$35,6),"")
A12: 40 | B12: =IFERROR($A12/INDEX('Yield Curve'!$I$28:$I$35,2),"") | C12: =IFERROR($A12/INDEX('Yield Curve'!$I$28:$I$35,3),"") | D12: =IFERROR($A12/INDEX('Yield Curve'!$I$28:$I$35,4),"") | E12: =IFERROR($A12/INDEX('Yield Curve'!$I$28:$I$35,5),"") | F12: =IFERROR($A12/INDEX('Yield Curve'!$I$28:$I$35,6),"")
A13: 50 | B13: =IFERROR($A13/INDEX('Yield Curve'!$I$28:$I$35,2),"") | C13: =IFERROR($A13/INDEX('Yield Curve'!$I$28:$I$35,3),"") | D13: =IFERROR($A13/INDEX('Yield Curve'!$I$28:$I$35,4),"") | E13: =IFERROR($A13/INDEX('Yield Curve'!$I$28:$I$35,5),"") | F13: =IFERROR($A13/INDEX('Yield Curve'!$I$28:$I$35,6),"")
A16: AGENTS ON THE PHONE NEEDED TO WORK THAT VOLUME
A17: Sales/day target | B17: cap at 2 | C17: cap at 3 | D17: cap at 4 | E17: cap at 5 | F17: cap at 6
A18: 5 | B18: =IFERROR($A18/INDEX('Yield Curve'!$I$28:$I$35,2)*INDEX('Yield Curve'!$H$28:$H$35,2)/Planner!$B$19,"") | C18: =IFERROR($A18/INDEX('Yield Curve'!$I$28:$I$35,3)*INDEX('Yield Curve'!$H$28:$H$35,3)/Planner!$B$19,"") | D18: =IFERROR($A18/INDEX('Yield Curve'!$I$28:$I$35,4)*INDEX('Yield Curve'!$H$28:$H$35,4)/Planner!$B$19,"") | E18: =IFERROR($A18/INDEX('Yield Curve'!$I$28:$I$35,5)*INDEX('Yield Curve'!$H$28:$H$35,5)/Planner!$B$19,"") | F18: =IFERROR($A18/INDEX('Yield Curve'!$I$28:$I$35,6)*INDEX('Yield Curve'!$H$28:$H$35,6)/Planner!$B$19,"")
A19: 10 | B19: =IFERROR($A19/INDEX('Yield Curve'!$I$28:$I$35,2)*INDEX('Yield Curve'!$H$28:$H$35,2)/Planner!$B$19,"") | C19: =IFERROR($A19/INDEX('Yield Curve'!$I$28:$I$35,3)*INDEX('Yield Curve'!$H$28:$H$35,3)/Planner!$B$19,"") | D19: =IFERROR($A19/INDEX('Yield Curve'!$I$28:$I$35,4)*INDEX('Yield Curve'!$H$28:$H$35,4)/Planner!$B$19,"") | E19: =IFERROR($A19/INDEX('Yield Curve'!$I$28:$I$35,5)*INDEX('Yield Curve'!$H$28:$H$35,5)/Planner!$B$19,"") | F19: =IFERROR($A19/INDEX('Yield Curve'!$I$28:$I$35,6)*INDEX('Yield Curve'!$H$28:$H$35,6)/Planner!$B$19,"")
A20: 15 | B20: =IFERROR($A20/INDEX('Yield Curve'!$I$28:$I$35,2)*INDEX('Yield Curve'!$H$28:$H$35,2)/Planner!$B$19,"") | C20: =IFERROR($A20/INDEX('Yield Curve'!$I$28:$I$35,3)*INDEX('Yield Curve'!$H$28:$H$35,3)/Planner!$B$19,"") | D20: =IFERROR($A20/INDEX('Yield Curve'!$I$28:$I$35,4)*INDEX('Yield Curve'!$H$28:$H$35,4)/Planner!$B$19,"") | E20: =IFERROR($A20/INDEX('Yield Curve'!$I$28:$I$35,5)*INDEX('Yield Curve'!$H$28:$H$35,5)/Planner!$B$19,"") | F20: =IFERROR($A20/INDEX('Yield Curve'!$I$28:$I$35,6)*INDEX('Yield Curve'!$H$28:$H$35,6)/Planner!$B$19,"")
A21: 20 | B21: =IFERROR($A21/INDEX('Yield Curve'!$I$28:$I$35,2)*INDEX('Yield Curve'!$H$28:$H$35,2)/Planner!$B$19,"") | C21: =IFERROR($A21/INDEX('Yield Curve'!$I$28:$I$35,3)*INDEX('Yield Curve'!$H$28:$H$35,3)/Planner!$B$19,"") | D21: =IFERROR($A21/INDEX('Yield Curve'!$I$28:$I$35,4)*INDEX('Yield Curve'!$H$28:$H$35,4)/Planner!$B$19,"") | E21: =IFERROR($A21/INDEX('Yield Curve'!$I$28:$I$35,5)*INDEX('Yield Curve'!$H$28:$H$35,5)/Planner!$B$19,"") | F21: =IFERROR($A21/INDEX('Yield Curve'!$I$28:$I$35,6)*INDEX('Yield Curve'!$H$28:$H$35,6)/Planner!$B$19,"")
A22: 25 | B22: =IFERROR($A22/INDEX('Yield Curve'!$I$28:$I$35,2)*INDEX('Yield Curve'!$H$28:$H$35,2)/Planner!$B$19,"") | C22: =IFERROR($A22/INDEX('Yield Curve'!$I$28:$I$35,3)*INDEX('Yield Curve'!$H$28:$H$35,3)/Planner!$B$19,"") | D22: =IFERROR($A22/INDEX('Yield Curve'!$I$28:$I$35,4)*INDEX('Yield Curve'!$H$28:$H$35,4)/Planner!$B$19,"") | E22: =IFERROR($A22/INDEX('Yield Curve'!$I$28:$I$35,5)*INDEX('Yield Curve'!$H$28:$H$35,5)/Planner!$B$19,"") | F22: =IFERROR($A22/INDEX('Yield Curve'!$I$28:$I$35,6)*INDEX('Yield Curve'!$H$28:$H$35,6)/Planner!$B$19,"")
A23: 30 | B23: =IFERROR($A23/INDEX('Yield Curve'!$I$28:$I$35,2)*INDEX('Yield Curve'!$H$28:$H$35,2)/Planner!$B$19,"") | C23: =IFERROR($A23/INDEX('Yield Curve'!$I$28:$I$35,3)*INDEX('Yield Curve'!$H$28:$H$35,3)/Planner!$B$19,"") | D23: =IFERROR($A23/INDEX('Yield Curve'!$I$28:$I$35,4)*INDEX('Yield Curve'!$H$28:$H$35,4)/Planner!$B$19,"") | E23: =IFERROR($A23/INDEX('Yield Curve'!$I$28:$I$35,5)*INDEX('Yield Curve'!$H$28:$H$35,5)/Planner!$B$19,"") | F23: =IFERROR($A23/INDEX('Yield Curve'!$I$28:$I$35,6)*INDEX('Yield Curve'!$H$28:$H$35,6)/Planner!$B$19,"")
A24: 40 | B24: =IFERROR($A24/INDEX('Yield Curve'!$I$28:$I$35,2)*INDEX('Yield Curve'!$H$28:$H$35,2)/Planner!$B$19,"") | C24: =IFERROR($A24/INDEX('Yield Curve'!$I$28:$I$35,3)*INDEX('Yield Curve'!$H$28:$H$35,3)/Planner!$B$19,"") | D24: =IFERROR($A24/INDEX('Yield Curve'!$I$28:$I$35,4)*INDEX('Yield Curve'!$H$28:$H$35,4)/Planner!$B$19,"") | E24: =IFERROR($A24/INDEX('Yield Curve'!$I$28:$I$35,5)*INDEX('Yield Curve'!$H$28:$H$35,5)/Planner!$B$19,"") | F24: =IFERROR($A24/INDEX('Yield Curve'!$I$28:$I$35,6)*INDEX('Yield Curve'!$H$28:$H$35,6)/Planner!$B$19,"")
A25: 50 | B25: =IFERROR($A25/INDEX('Yield Curve'!$I$28:$I$35,2)*INDEX('Yield Curve'!$H$28:$H$35,2)/Planner!$B$19,"") | C25: =IFERROR($A25/INDEX('Yield Curve'!$I$28:$I$35,3)*INDEX('Yield Curve'!$H$28:$H$35,3)/Planner!$B$19,"") | D25: =IFERROR($A25/INDEX('Yield Curve'!$I$28:$I$35,4)*INDEX('Yield Curve'!$H$28:$H$35,4)/Planner!$B$19,"") | E25: =IFERROR($A25/INDEX('Yield Curve'!$I$28:$I$35,5)*INDEX('Yield Curve'!$H$28:$H$35,5)/Planner!$B$19,"") | F25: =IFERROR($A25/INDEX('Yield Curve'!$I$28:$I$35,6)*INDEX('Yield Curve'!$H$28:$H$35,6)/Planner!$B$19,"")
A28: COST PER SALE AT EACH CAP
A29: Cost per fresh lead | B29: cap at 2 | C29: cap at 3 | D29: cap at 4 | E29: cap at 5 | F29: cap at 6
A30: 1 | B30: =IFERROR(($A30+Planner!$B$26*INDEX('Yield Curve'!$H$28:$H$35,2))/INDEX('Yield Curve'!$I$28:$I$35,2),"") | C30: =IFERROR(($A30+Planner!$B$26*INDEX('Yield Curve'!$H$28:$H$35,3))/INDEX('Yield Curve'!$I$28:$I$35,3),"") | D30: =IFERROR(($A30+Planner!$B$26*INDEX('Yield Curve'!$H$28:$H$35,4))/INDEX('Yield Curve'!$I$28:$I$35,4),"") | E30: =IFERROR(($A30+Planner!$B$26*INDEX('Yield Curve'!$H$28:$H$35,5))/INDEX('Yield Curve'!$I$28:$I$35,5),"") | F30: =IFERROR(($A30+Planner!$B$26*INDEX('Yield Curve'!$H$28:$H$35,6))/INDEX('Yield Curve'!$I$28:$I$35,6),"")
A31: 2 | B31: =IFERROR(($A31+Planner!$B$26*INDEX('Yield Curve'!$H$28:$H$35,2))/INDEX('Yield Curve'!$I$28:$I$35,2),"") | C31: =IFERROR(($A31+Planner!$B$26*INDEX('Yield Curve'!$H$28:$H$35,3))/INDEX('Yield Curve'!$I$28:$I$35,3),"") | D31: =IFERROR(($A31+Planner!$B$26*INDEX('Yield Curve'!$H$28:$H$35,4))/INDEX('Yield Curve'!$I$28:$I$35,4),"") | E31: =IFERROR(($A31+Planner!$B$26*INDEX('Yield Curve'!$H$28:$H$35,5))/INDEX('Yield Curve'!$I$28:$I$35,5),"") | F31: =IFERROR(($A31+Planner!$B$26*INDEX('Yield Curve'!$H$28:$H$35,6))/INDEX('Yield Curve'!$I$28:$I$35,6),"")
A32: 3 | B32: =IFERROR(($A32+Planner!$B$26*INDEX('Yield Curve'!$H$28:$H$35,2))/INDEX('Yield Curve'!$I$28:$I$35,2),"") | C32: =IFERROR(($A32+Planner!$B$26*INDEX('Yield Curve'!$H$28:$H$35,3))/INDEX('Yield Curve'!$I$28:$I$35,3),"") | D32: =IFERROR(($A32+Planner!$B$26*INDEX('Yield Curve'!$H$28:$H$35,4))/INDEX('Yield Curve'!$I$28:$I$35,4),"") | E32: =IFERROR(($A32+Planner!$B$26*INDEX('Yield Curve'!$H$28:$H$35,5))/INDEX('Yield Curve'!$I$28:$I$35,5),"") | F32: =IFERROR(($A32+Planner!$B$26*INDEX('Yield Curve'!$H$28:$H$35,6))/INDEX('Yield Curve'!$I$28:$I$35,6),"")
A33: 5 | B33: =IFERROR(($A33+Planner!$B$26*INDEX('Yield Curve'!$H$28:$H$35,2))/INDEX('Yield Curve'!$I$28:$I$35,2),"") | C33: =IFERROR(($A33+Planner!$B$26*INDEX('Yield Curve'!$H$28:$H$35,3))/INDEX('Yield Curve'!$I$28:$I$35,3),"") | D33: =IFERROR(($A33+Planner!$B$26*INDEX('Yield Curve'!$H$28:$H$35,4))/INDEX('Yield Curve'!$I$28:$I$35,4),"") | E33: =IFERROR(($A33+Planner!$B$26*INDEX('Yield Curve'!$H$28:$H$35,5))/INDEX('Yield Curve'!$I$28:$I$35,5),"") | F33: =IFERROR(($A33+Planner!$B$26*INDEX('Yield Curve'!$H$28:$H$35,6))/INDEX('Yield Curve'!$I$28:$I$35,6),"")
A34: 8 | B34: =IFERROR(($A34+Planner!$B$26*INDEX('Yield Curve'!$H$28:$H$35,2))/INDEX('Yield Curve'!$I$28:$I$35,2),"") | C34: =IFERROR(($A34+Planner!$B$26*INDEX('Yield Curve'!$H$28:$H$35,3))/INDEX('Yield Curve'!$I$28:$I$35,3),"") | D34: =IFERROR(($A34+Planner!$B$26*INDEX('Yield Curve'!$H$28:$H$35,4))/INDEX('Yield Curve'!$I$28:$I$35,4),"") | E34: =IFERROR(($A34+Planner!$B$26*INDEX('Yield Curve'!$H$28:$H$35,5))/INDEX('Yield Curve'!$I$28:$I$35,5),"") | F34: =IFERROR(($A34+Planner!$B$26*INDEX('Yield Curve'!$H$28:$H$35,6))/INDEX('Yield Curve'!$I$28:$I$35,6),"")
A35: 12 | B35: =IFERROR(($A35+Planner!$B$26*INDEX('Yield Curve'!$H$28:$H$35,2))/INDEX('Yield Curve'!$I$28:$I$35,2),"") | C35: =IFERROR(($A35+Planner!$B$26*INDEX('Yield Curve'!$H$28:$H$35,3))/INDEX('Yield Curve'!$I$28:$I$35,3),"") | D35: =IFERROR(($A35+Planner!$B$26*INDEX('Yield Curve'!$H$28:$H$35,4))/INDEX('Yield Curve'!$I$28:$I$35,4),"") | E35: =IFERROR(($A35+Planner!$B$26*INDEX('Yield Curve'!$H$28:$H$35,5))/INDEX('Yield Curve'!$I$28:$I$35,5),"") | F35: =IFERROR(($A35+Planner!$B$26*INDEX('Yield Curve'!$H$28:$H$35,6))/INDEX('Yield Curve'!$I$28:$I$35,6),"")
A37: The lowest cost per sale in each row of the bottom grid is the cap you should be running at that lead price. Cheap leads reward a tight cap and high volume; expensive leads reward working each lead harder.

Sheet Yield Curve
A1: Yield Curve
A2: What each successive attempt on a lead is actually worth.
A4: A · RECALCULATED FROM 'PASTE CALLS' (blank until you paste)
A5: Attempt | B5: Dials | C5: Connects | D5: Sales | E5: Still in play | F5: Connect rate | G5: Sales per 100 dials | H5: Dials per sale
A6: 1 | B6: =COUNTIFS('Paste Calls'!$B$5:$B$100000,$A6) | C6: =COUNTIFS('Paste Calls'!$B$5:$B$100000,$A6,'Paste Calls'!$D$5:$D$100000,">"&Capacity!$B$26) | D6: =COUNTIFS('Paste Calls'!$B$5:$B$100000,$A6,'Paste Calls'!$E$5:$E$100000,Capacity!$B$27) | E6: =IFERROR(B6/$B$6,"") | F6: =IFERROR(C6/B6,"") | G6: =IFERROR(100*D6/B6,"") | H6: =IFERROR(B6/D6,"")
A7: 2 | B7: =COUNTIFS('Paste Calls'!$B$5:$B$100000,$A7) | C7: =COUNTIFS('Paste Calls'!$B$5:$B$100000,$A7,'Paste Calls'!$D$5:$D$100000,">"&Capacity!$B$26) | D7: =COUNTIFS('Paste Calls'!$B$5:$B$100000,$A7,'Paste Calls'!$E$5:$E$100000,Capacity!$B$27) | E7: =IFERROR(B7/$B$6,"") | F7: =IFERROR(C7/B7,"") | G7: =IFERROR(100*D7/B7,"") | H7: =IFERROR(B7/D7,"")
A8: 3 | B8: =COUNTIFS('Paste Calls'!$B$5:$B$100000,$A8) | C8: =COUNTIFS('Paste Calls'!$B$5:$B$100000,$A8,'Paste Calls'!$D$5:$D$100000,">"&Capacity!$B$26) | D8: =COUNTIFS('Paste Calls'!$B$5:$B$100000,$A8,'Paste Calls'!$E$5:$E$100000,Capacity!$B$27) | E8: =IFERROR(B8/$B$6,"") | F8: =IFERROR(C8/B8,"") | G8: =IFERROR(100*D8/B8,"") | H8: =IFERROR(B8/D8,"")
A9: 4 | B9: =COUNTIFS('Paste Calls'!$B$5:$B$100000,$A9) | C9: =COUNTIFS('Paste Calls'!$B$5:$B$100000,$A9,'Paste Calls'!$D$5:$D$100000,">"&Capacity!$B$26) | D9: =COUNTIFS('Paste Calls'!$B$5:$B$100000,$A9,'Paste Calls'!$E$5:$E$100000,Capacity!$B$27) | E9: =IFERROR(B9/$B$6,"") | F9: =IFERROR(C9/B9,"") | G9: =IFERROR(100*D9/B9,"") | H9: =IFERROR(B9/D9,"")
A10: 5 | B10: =COUNTIFS('Paste Calls'!$B$5:$B$100000,$A10) | C10: =COUNTIFS('Paste Calls'!$B$5:$B$100000,$A10,'Paste Calls'!$D$5:$D$100000,">"&Capacity!$B$26) | D10: =COUNTIFS('Paste Calls'!$B$5:$B$100000,$A10,'Paste Calls'!$E$5:$E$100000,Capacity!$B$27) | E10: =IFERROR(B10/$B$6,"") | F10: =IFERROR(C10/B10,"") | G10: =IFERROR(100*D10/B10,"") | H10: =IFERROR(B10/D10,"")
A11: 6 | B11: =COUNTIFS('Paste Calls'!$B$5:$B$100000,$A11) | C11: =COUNTIFS('Paste Calls'!$B$5:$B$100000,$A11,'Paste Calls'!$D$5:$D$100000,">"&Capacity!$B$26) | D11: =COUNTIFS('Paste Calls'!$B$5:$B$100000,$A11,'Paste Calls'!$E$5:$E$100000,Capacity!$B$27) | E11: =IFERROR(B11/$B$6,"") | F11: =IFERROR(C11/B11,"") | G11: =IFERROR(100*D11/B11,"") | H11: =IFERROR(B11/D11,"")
A12: 7 | B12: =COUNTIFS('Paste Calls'!$B$5:$B$100000,$A12) | C12: =COUNTIFS('Paste Calls'!$B$5:$B$100000,$A12,'Paste Calls'!$D$5:$D$100000,">"&Capacity!$B$26) | D12: =COUNTIFS('Paste Calls'!$B$5:$B$100000,$A12,'Paste Calls'!$E$5:$E$100000,Capacity!$B$27) | E12: =IFERROR(B12/$B$6,"") | F12: =IFERROR(C12/B12,"") | G12: =IFERROR(100*D12/B12,"") | H12: =IFERROR(B12/D12,"")
A13: 8 | B13: =COUNTIFS('Paste Calls'!$B$5:$B$100000,$A13) | C13: =COUNTIFS('Paste Calls'!$B$5:$B$100000,$A13,'Paste Calls'!$D$5:$D$100000,">"&Capacity!$B$26) | D13: =COUNTIFS('Paste Calls'!$B$5:$B$100000,$A13,'Paste Calls'!$E$5:$E$100000,Capacity!$B$27) | E13: =IFERROR(B13/$B$6,"") | F13: =IFERROR(C13/B13,"") | G13: =IFERROR(100*D13/B13,"") | H13: =IFERROR(B13/D13,"")
A15: B · BASELINE — MEASURED 20 MAR – 1 SEP 2026
A16: Attempt | B16: Dials | C16: Connects | D16: Sales | E16: Still in play | F16: Connect rate | G16: Sales per 100 dials | H16: Dials per sale
A17: 1 | B17: 7754 | C17: 3510 | D17: 213 | E17: =IFERROR(B17/$B$17,"") | F17: =IFERROR(C17/B17,"") | G17: =IFERROR(100*D17/B17,"") | H17: =IFERROR(B17/D17,"")
A18: 2 | B18: 6372 | C18: 2580 | D18: 183 | E18: =IFERROR(B18/$B$17,"") | F18: =IFERROR(C18/B18,"") | G18: =IFERROR(100*D18/B18,"") | H18: =IFERROR(B18/D18,"")
A19: 3 | B19: 5134 | C19: 1816 | D19: 113 | E19: =IFERROR(B19/$B$17,"") | F19: =IFERROR(C19/B19,"") | G19: =IFERROR(100*D19/B19,"") | H19: =IFERROR(B19/D19,"")
A20: 4 | B20: 3931 | C20: 1329 | D20: 62 | E20: =IFERROR(B20/$B$17,"") | F20: =IFERROR(C20/B20,"") | G20: =IFERROR(100*D20/B20,"") | H20: =IFERROR(B20/D20,"")
A21: 5 | B21: 2111 | C21: 637 | D21: 24 | E21: =IFERROR(B21/$B$17,"") | F21: =IFERROR(C21/B21,"") | G21: =IFERROR(100*D21/B21,"") | H21: =IFERROR(B21/D21,"")
A22: 6 | B22: 493 | C22: 196 | D22: 10 | E22: =IFERROR(B22/$B$17,"") | F22: =IFERROR(C22/B22,"") | G22: =IFERROR(100*D22/B22,"") | H22: =IFERROR(B22/D22,"")
A23: 7 | B23: 144 | C23: 58 | D23: 8 | E23: =IFERROR(B23/$B$17,"") | F23: =IFERROR(C23/B23,"") | G23: =IFERROR(100*D23/B23,"") | H23: =IFERROR(B23/D23,"")
A24: 8 | B24: 59 | C24: 27 | D24: 2 | E24: =IFERROR(B24/$B$17,"") | F24: =IFERROR(C24/B24,"") | G24: =IFERROR(100*D24/B24,"") | H24: =IFERROR(B24/D24,"")
A26: C · CUMULATIVE BY ATTEMPT CAP — THIS IS WHAT THE PLANNER READS
A27: Cap at | B27: Dials/lead (auto) | C27: Sales/lead (auto) | D27: Per 100 (auto) | E27: Dials/lead (baseline) | F27: Sales/lead (baseline) | G27: Per 100 (baseline) | H27: Dials/lead IN USE | I27: Sales/lead IN USE | J27: Break-even lead price (× cost of one dial)
A28: 1 | B28: =IFERROR(SUMIF($A$6:$A$13,"<="&$A28,$B$6:$B$13)/$B$6,"") | C28: =IFERROR(SUMIF($A$6:$A$13,"<="&$A28,$D$6:$D$13)/$B$6,"") | D28: =IFERROR(100*C28/B28,"") | E28: =IFERROR(SUMIF($A$17:$A$24,"<="&$A28,$B$17:$B$24)/$B$17,"") | F28: =IFERROR(SUMIF($A$17:$A$24,"<="&$A28,$D$17:$D$24)/$B$17,"") | G28: =IFERROR(100*F28/E28,"") | H28: =IF(Planner!$B$12="Auto",B28,E28) | I28: =IF(Planner!$B$12="Auto",C28,F28) | J28: n/a
A29: 2 | B29: =IFERROR(SUMIF($A$6:$A$13,"<="&$A29,$B$6:$B$13)/$B$6,"") | C29: =IFERROR(SUMIF($A$6:$A$13,"<="&$A29,$D$6:$D$13)/$B$6,"") | D29: =IFERROR(100*C29/B29,"") | E29: =IFERROR(SUMIF($A$17:$A$24,"<="&$A29,$B$17:$B$24)/$B$17,"") | F29: =IFERROR(SUMIF($A$17:$A$24,"<="&$A29,$D$17:$D$24)/$B$17,"") | G29: =IFERROR(100*F29/E29,"") | H29: =IF(Planner!$B$12="Auto",B29,E29) | I29: =IF(Planner!$B$12="Auto",C29,F29) | J29: =IFERROR((H29-H28)*I28/(I29-I28)-H28,"")
A30: 3 | B30: =IFERROR(SUMIF($A$6:$A$13,"<="&$A30,$B$6:$B$13)/$B$6,"") | C30: =IFERROR(SUMIF($A$6:$A$13,"<="&$A30,$D$6:$D$13)/$B$6,"") | D30: =IFERROR(100*C30/B30,"") | E30: =IFERROR(SUMIF($A$17:$A$24,"<="&$A30,$B$17:$B$24)/$B$17,"") | F30: =IFERROR(SUMIF($A$17:$A$24,"<="&$A30,$D$17:$D$24)/$B$17,"") | G30: =IFERROR(100*F30/E30,"") | H30: =IF(Planner!$B$12="Auto",B30,E30) | I30: =IF(Planner!$B$12="Auto",C30,F30) | J30: =IFERROR((H30-H29)*I29/(I30-I29)-H29,"")
A31: 4 | B31: =IFERROR(SUMIF($A$6:$A$13,"<="&$A31,$B$6:$B$13)/$B$6,"") | C31: =IFERROR(SUMIF($A$6:$A$13,"<="&$A31,$D$6:$D$13)/$B$6,"") | D31: =IFERROR(100*C31/B31,"") | E31: =IFERROR(SUMIF($A$17:$A$24,"<="&$A31,$B$17:$B$24)/$B$17,"") | F31: =IFERROR(SUMIF($A$17:$A$24,"<="&$A31,$D$17:$D$24)/$B$17,"") | G31: =IFERROR(100*F31/E31,"") | H31: =IF(Planner!$B$12="Auto",B31,E31) | I31: =IF(Planner!$B$12="Auto",C31,F31) | J31: =IFERROR((H31-H30)*I30/(I31-I30)-H30,"")
A32: 5 | B32: =IFERROR(SUMIF($A$6:$A$13,"<="&$A32,$B$6:$B$13)/$B$6,"") | C32: =IFERROR(SUMIF($A$6:$A$13,"<="&$A32,$D$6:$D$13)/$B$6,"") | D32: =IFERROR(100*C32/B32,"") | E32: =IFERROR(SUMIF($A$17:$A$24,"<="&$A32,$B$17:$B$24)/$B$17,"") | F32: =IFERROR(SUMIF($A$17:$A$24,"<="&$A32,$D$17:$D$24)/$B$17,"") | G32: =IFERROR(100*F32/E32,"") | H32: =IF(Planner!$B$12="Auto",B32,E32) | I32: =IF(Planner!$B$12="Auto",C32,F32) | J32: =IFERROR((H32-H31)*I31/(I32-I31)-H31,"")
A33: 6 | B33: =IFERROR(SUMIF($A$6:$A$13,"<="&$A33,$B$6:$B$13)/$B$6,"") | C33: =IFERROR(SUMIF($A$6:$A$13,"<="&$A33,$D$6:$D$13)/$B$6,"") | D33: =IFERROR(100*C33/B33,"") | E33: =IFERROR(SUMIF($A$17:$A$24,"<="&$A33,$B$17:$B$24)/$B$17,"") | F33: =IFERROR(SUMIF($A$17:$A$24,"<="&$A33,$D$17:$D$24)/$B$17,"") | G33: =IFERROR(100*F33/E33,"") | H33: =IF(Planner!$B$12="Auto",B33,E33) | I33: =IF(Planner!$B$12="Auto",C33,F33) | J33: =IFERROR((H33-H32)*I32/(I33-I32)-H32,"")
A34: 7 | B34: =IFERROR(SUMIF($A$6:$A$13,"<="&$A34,$B$6:$B$13)/$B$6,"") | C34: =IFERROR(SUMIF($A$6:$A$13,"<="&$A34,$D$6:$D$13)/$B$6,"") | D34: =IFERROR(100*C34/B34,"") | E34: =IFERROR(SUMIF($A$17:$A$24,"<="&$A34,$B$17:$B$24)/$B$17,"") | F34: =IFERROR(SUMIF($A$17:$A$24,"<="&$A34,$D$17:$D$24)/$B$17,"") | G34: =IFERROR(100*F34/E34,"") | H34: =IF(Planner!$B$12="Auto",B34,E34) | I34: =IF(Planner!$B$12="Auto",C34,F34) | J34: =IFERROR((H34-H33)*I33/(I34-I33)-H33,"")
A35: 8 | B35: =IFERROR(SUMIF($A$6:$A$13,"<="&$A35,$B$6:$B$13)/$B$6,"") | C35: =IFERROR(SUMIF($A$6:$A$13,"<="&$A35,$D$6:$D$13)/$B$6,"") | D35: =IFERROR(100*C35/B35,"") | E35: =IFERROR(SUMIF($A$17:$A$24,"<="&$A35,$B$17:$B$24)/$B$17,"") | F35: =IFERROR(SUMIF($A$17:$A$24,"<="&$A35,$D$17:$D$24)/$B$17,"") | G35: =IFERROR(100*F35/E35,"") | H35: =IF(Planner!$B$12="Auto",B35,E35) | I35: =IF(Planner!$B$12="Auto",C35,F35) | J35: =IFERROR((H35-H34)*I34/(I35-I34)-H34,"")
A38: Read column K like this: raising the cap from 3 to 4 is worth doing as long as a fresh lead costs more than 1.7× what one dial costs in agent time.
A39: Tightening the cap only pays when fresh leads are cheap enough to replace the attempts you give up. If agents are sitting at part occupancy, a spare dial is nearly free and the cap is not your problem — supply is.
A40: 'Still in play' is the share of leads that survive to receive that attempt. It falls because leads sell, refuse, or turn out to be junk, not only because the team stops dialling.
A41: Treat attempts 6 and beyond with suspicion. Those rows look strong, but almost nothing reaches them by policy — they are leads an agent chose to keep chasing, usually a booked callback. That is a hand-picked group, not evidence that a 7th cold dial pays. Do not plan above a cap of 5 on it.

Sheet Capacity
A1: Capacity
A2: Is the dials-per-agent-day number on the Planner physically possible?
A4: WHAT A REAL AGENT-DAY LOOKED LIKE (172 agent-days, Mar-Aug 2026)
B5: Dials | C5: Connects | D5: Talk hours
A6: Quiet day (25th percentile) | B6: 82 | C6: 37 | D6: 2.3
A7: Typical day (median) | B7: 129 | C7: 56 | D7: 3.3
A8: Strong day (75th percentile) | B8: 198 | C8: 80 | D8: 4.4
A9: Best days (90th percentile) | B9: 295 | C9: 100 | D9: 4.9
A11: SANITY-CHECK YOUR PLANNING ASSUMPTION
A12: Dials per agent-day assumed on the Planner | B12: =Planner!$B$19
A13: Connect rate you expect | B13: 0.4 | C13: Blended across attempts 1 to the cap.
A14: Average talk time per connect (minutes) | B14: 3.5
A15: Seconds of wrap and dialling per dial | B15: 25
A16: Talk hours implied | B16: =IFERROR(B12*B13*B14/60,"")
A17: Wrap and dial hours implied | B17: =IFERROR(B12*B15/3600,"")
A18: Total occupied hours | B18: =IFERROR(B16+B17,"")
A19: Paid hours per agent-day | B19: =Planner!$B$25
A20: Occupancy | B20: =IFERROR(B18/B19,"")
A21: Verdict | B21: =IF(B20>0.95,"IMPOSSIBLE — lower the dials assumption",IF(B20>0.85,"VERY TIGHT — no room for breaks or admin",IF(B20<0.5,"LOTS OF SLACK — the phones are not the constraint","REALISTIC")))
A23: SETTINGS USED ELSEWHERE
A24: Measured occupancy, Mar-Aug 2026 | B24: 0.44 | C24: 3.3 talk hours against a 7.5 hour shift.
A26: A call counts as connected above (seconds) | B26: 20 | C26: 12.3% of calls last exactly 20s — that is the dialler's ring timeout.
A27: Outcome value that means a sale | B27: Success | C27: Must match the text in your export exactly.
A29: Occupancy below about 60% says the team is starved of list, not short of hours: they have time on the clock and nothing worth dialling. That is the state the measured data is in, and it is why buying more leads works before hiring does.

Sheet List Health
A1: List Health
A2: How much genuinely workable list is left, and how long it lasts.
A4: THE LIST RIGHT NOW (from Paste Leads)
A5: Today | B5: =TODAY()
A6: Leads loaded | B6: =COUNTA('Paste Leads'!$A$5:$A$100000)
A7: Arrived inside the freshness window | B7: =COUNTIFS('Paste Leads'!$B$5:$B$100000,">="&(TODAY()-Planner!$B$11)) | C7: Lead date within the Planner's retirement age.
A8: …of those, still open and under the attempt cap | B8: =COUNTIFS('Paste Leads'!$B$5:$B$100000,">="&(TODAY()-Planner!$B$11),'Paste Leads'!$C$5:$C$100000,"<"&Planner!$B$10,'Paste Leads'!$D$5:$D$100000,"<>Success",'Paste Leads'!$D$5:$D$100000,"<>Not interested",'Paste Leads'!$D$5:$D$100000,"<>Invalid",'Paste Leads'!$D$5:$D$100000,"<>Unqualified") | C8: This is your real workable stock.
A9: Open but already at the attempt cap | B9: =COUNTIFS('Paste Leads'!$B$5:$B$100000,">="&(TODAY()-Planner!$B$11),'Paste Leads'!$C$5:$C$100000,">="&Planner!$B$10,'Paste Leads'!$D$5:$D$100000,"<>Success",'Paste Leads'!$D$5:$D$100000,"<>Not interested",'Paste Leads'!$D$5:$D$100000,"<>Invalid",'Paste Leads'!$D$5:$D$100000,"<>Unqualified") | C9: Burnt inside the window — the symptom of running short on fresh list.
A10: Open but past the retirement age | B10: =COUNTIFS('Paste Leads'!$B$5:$B$100000,"<"&(TODAY()-Planner!$B$11),'Paste Leads'!$D$5:$D$100000,"<>Success",'Paste Leads'!$D$5:$D$100000,"<>Not interested",'Paste Leads'!$D$5:$D$100000,"<>Invalid",'Paste Leads'!$D$5:$D$100000,"<>Unqualified") | C10: Worth roughly half. Archive rather than dial.
A12: RUNWAY
A13: Workable stock | B13: =B8
A14: Leads consumed per day at plan | B14: =Planner!$B$32
A15: Days of cover left | B15: =IFERROR(B13/B14,"")
A16: Target days of cover | B16: =Planner!$B$45
A17: Verdict | B17: =IF(B15<1,"EMPTY — agents are re-dialling exhausted list today",IF(B15<B16,"BELOW BUFFER — order now",IF(B15>B16*4,"OVERSTOCKED — leads will age out before they are worked","HEALTHY")))
A19: AGEING PROFILE
A20: Lead age | B20: Open leads | C20: What to do with them
A21: 0–7 days | B21: =COUNTIFS('Paste Leads'!$B$5:$B$100000,"<="&(TODAY()-0),'Paste Leads'!$B$5:$B$100000,">="&(TODAY()-7),'Paste Leads'!$D$5:$D$100000,"<>Success",'Paste Leads'!$D$5:$D$100000,"<>Not interested",'Paste Leads'!$D$5:$D$100000,"<>Invalid",'Paste Leads'!$D$5:$D$100000,"<>Unqualified") | C21: Prime. Should be on attempt 1 or 2.
A22: 8–14 days | B22: =COUNTIFS('Paste Leads'!$B$5:$B$100000,"<="&(TODAY()-8),'Paste Leads'!$B$5:$B$100000,">="&(TODAY()-14),'Paste Leads'!$D$5:$D$100000,"<>Success",'Paste Leads'!$D$5:$D$100000,"<>Not interested",'Paste Leads'!$D$5:$D$100000,"<>Invalid",'Paste Leads'!$D$5:$D$100000,"<>Unqualified") | C22: Still strong. Attempts 2 to 3.
A23: 15–30 days | B23: =COUNTIFS('Paste Leads'!$B$5:$B$100000,"<="&(TODAY()-15),'Paste Leads'!$B$5:$B$100000,">="&(TODAY()-30),'Paste Leads'!$D$5:$D$100000,"<>Success",'Paste Leads'!$D$5:$D$100000,"<>Not interested",'Paste Leads'!$D$5:$D$100000,"<>Invalid",'Paste Leads'!$D$5:$D$100000,"<>Unqualified") | C23: Last of the value. Finish the cap here.
A24: 31–60 days | B24: =COUNTIFS('Paste Leads'!$B$5:$B$100000,"<="&(TODAY()-31),'Paste Leads'!$B$5:$B$100000,">="&(TODAY()-60),'Paste Leads'!$D$5:$D$100000,"<>Success",'Paste Leads'!$D$5:$D$100000,"<>Not interested",'Paste Leads'!$D$5:$D$100000,"<>Invalid",'Paste Leads'!$D$5:$D$100000,"<>Unqualified") | C24: Yield roughly halves. Stop unless nothing else is loaded.
A25: 61+ days | B25: =COUNTIFS('Paste Leads'!$B$5:$B$100000,"<="&(TODAY()-61),'Paste Leads'!$B$5:$B$100000,">="&(TODAY()-3650),'Paste Leads'!$D$5:$D$100000,"<>Success",'Paste Leads'!$D$5:$D$100000,"<>Not interested",'Paste Leads'!$D$5:$D$100000,"<>Invalid",'Paste Leads'!$D$5:$D$100000,"<>Unqualified") | C25: Effectively dead. 0.59 sales per 100 dials in the measured data.

Sheet Paste Calls
A1: Paste Calls
A2: One row per call. Airtable › Adversus Ireland › Databowl LeadId, Call # for Lead, Date, Call Duration, Lead Status. Paste your export into A5.
G3: what it should look like
A4: Lead ID | B4: Attempt no. | C4: Call date | D4: Duration (s) | E4: Outcome | G4: Lead ID | H4: Attempt no. | I4: Call date | J4: Duration (s) | K4: Outcome
G5: 1234567 | H5: 1 | I5: 2026-08-03 | J5: 14 | K5: Automatic redial
G6: 1234567 | H6: 2 | I6: 2026-08-06 | J6: 812 | K6: Success
G7: 1234568 | H7: 1 | I7: 2026-08-03 | J7: 20 | K7: Automatic redial

Sheet Paste Leads
A1: Paste Leads
A2: One row per lead. Airtable › Ireland Leads › Databowl Lead ID, Lead Date, Times Lead has been Called, Adversus Lead Status (single select). Paste your export into A5.
F3: what it should look like
A4: Lead ID | B4: Lead date | C4: Times called | D4: Status | F4: Lead ID | G4: Lead date | H4: Times called | I4: Status
F5: 1234567 | G5: 2026-08-03 | H5: 2 | I5: Success
F6: 1234568 | G6: 2026-08-03 | H6: 4 | I6: Automatic redial
F7: 1234569 | G7: 2026-08-04 | H7: 1 | I7: Private callback
